Workbook

Sheet Summary
A1: Issue log summary (updates automatically when Status / Priority are changed)
A3: Status | B3: All | C3: High | D3: Medium | E3: Low
A4: Resolved (business confirmed) | B4: =COUNTIF('Issue Log'!$H$2:$H$94,A4) -> 26 | C4: =COUNTIFS('Issue Log'!$H$2:$H$94,A4,'Issue Log'!$J$2:$J$94,"High") -> 10 | D4: =COUNTIFS('Issue Log'!$H$2:$H$94,A4,'Issue Log'!$J$2:$J$94,"Medium") -> 13 | E4: =COUNTIFS('Issue Log'!$H$2:$H$94,A4,'Issue Log'!$J$2:$J$94,"Low") -> 3
A5: Handled in model | B5: =COUNTIF('Issue Log'!$H$2:$H$94,A5) -> 30 | C5: =COUNTIFS('Issue Log'!$H$2:$H$94,A5,'Issue Log'!$J$2:$J$94,"High") -> 5 | D5: =COUNTIFS('Issue Log'!$H$2:$H$94,A5,'Issue Log'!$J$2:$J$94,"Medium") -> 9 | E5: =COUNTIFS('Issue Log'!$H$2:$H$94,A5,'Issue Log'!$J$2:$J$94,"Low") -> 16
A6: Open - business | B6: =COUNTIF('Issue Log'!$H$2:$H$94,A6) -> 23 | C6: =COUNTIFS('Issue Log'!$H$2:$H$94,A6,'Issue Log'!$J$2:$J$94,"High") -> 7 | D6: =COUNTIFS('Issue Log'!$H$2:$H$94,A6,'Issue Log'!$J$2:$J$94,"Medium") -> 11 | E6: =COUNTIFS('Issue Log'!$H$2:$H$94,A6,'Issue Log'!$J$2:$J$94,"Low") -> 5
A7: Open - ERP team | B7: =COUNTIF('Issue Log'!$H$2:$H$94,A7) -> 8 | C7: =COUNTIFS('Issue Log'!$H$2:$H$94,A7,'Issue Log'!$J$2:$J$94,"High") -> 2 | D7: =COUNTIFS('Issue Log'!$H$2:$H$94,A7,'Issue Log'!$J$2:$J$94,"Medium") -> 4 | E7: =COUNTIFS('Issue Log'!$H$2:$H$94,A7,'Issue Log'!$J$2:$J$94,"Low") -> 2
A8: Open - verify with full data | B8: =COUNTIF('Issue Log'!$H$2:$H$94,A8) -> 3 | C8: =COUNTIFS('Issue Log'!$H$2:$H$94,A8,'Issue Log'!$J$2:$J$94,"High") -> 0 | D8: =COUNTIFS('Issue Log'!$H$2:$H$94,A8,'Issue Log'!$J$2:$J$94,"Medium") -> 1 | E8: =COUNTIFS('Issue Log'!$H$2:$H$94,A8,'Issue Log'!$J$2:$J$94,"Low") -> 2
A9: Assumed - please confirm | B9: =COUNTIF('Issue Log'!$H$2:$H$94,A9) -> 3 | C9: =COUNTIFS('Issue Log'!$H$2:$H$94,A9,'Issue Log'!$J$2:$J$94,"High") -> 0 | D9: =COUNTIFS('Issue Log'!$H$2:$H$94,A9,'Issue Log'!$J$2:$J$94,"Medium") -> 1 | E9: =COUNTIFS('Issue Log'!$H$2:$H$94,A9,'Issue Log'!$J$2:$J$94,"Low") -> 2
A10: Total | B10: =SUM(B4:B9) -> 93 | C10: =SUM(C4:C9) -> 24 | D10: =SUM(D4:D9) -> 39 | E10: =SUM(E4:E9) -> 30
A12: Check: total equals number of issues | B12: =IF(B10=COUNTA('Issue Log'!$A$2:$A$94),"OK","MISMATCH - a status value is misspelled") -> OK
A14: Open by owner | B14: Open items
A15: Business (you) | B15: =COUNTIFS('Issue Log'!$K$2:$K$94,A15,'Issue Log'!$H$2:$H$94,"Open*")+COUNTIFS('Issue Log'!$K$2:$K$94,A15,'Issue Log'!$H$2:$H$94,"Assumed*") -> 27
A16: ERP team | B16: =COUNTIFS('Issue Log'!$K$2:$K$94,A16,'Issue Log'!$H$2:$H$94,"Open*")+COUNTIFS('Issue Log'!$K$2:$K$94,A16,'Issue Log'!$H$2:$H$94,"Assumed*") -> 8
A17: Data team | B17: =COUNTIFS('Issue Log'!$K$2:$K$94,A17,'Issue Log'!$H$2:$H$94,"Open*")+COUNTIFS('Issue Log'!$K$2:$K$94,A17,'Issue Log'!$H$2:$H$94,"Assumed*") -> 2

Sheet Issue Log
A1: ID | B1: Area | C1: Source file | D1: Issue found | E1: Evidence | F1: Impact if not handled | G1: How the model handles it | H1: Status | I1: Answer / resolution | J1: Priority | K1: Owner
A2: D-001 | B2: Scope | C2: All sample files | D2: Sample files cover Apr-Sep 2026, not from Apr 2025 as planned | E2: Sales, transfers, PO, inventory samples all start 1-Apr-2026 | F2: Forecasting needs a full year incl. festive season | G2: Prototype period set to 1-Apr-2025..15-Sep-2026 | H2: Resolved (business confirmed) | I2: Samples only; full ~1.5-year data will be provided | J2: High | K2: Business (you)
A3: D-002 | B3: Scope | C3: All sources | D3: Full 1.5-year data pull not yet received for any source | E3: Only samples loaded so far | F3: Nothing can be loaded for real yet | G3: Loaders will be built against the sample layouts | H3: Open - business | J3: High | K3: Business (you)
A4: D-003 | B4: Scope | C4: Return files | D4: Return files run past the 15-Sep cut-off | E4: 133 retail return rows and 40 domestic return rows dated 16-22 Sep | F4: Returns counted without their matching sales period | G4: Cut-off stored as a setting (meta.pipeline_setting); rows after it excluded at staging | H4: Resolved (business confirmed) | I4: Use data only up to 15-Sep-2026 | J4: Medium | K4: Data team
A5: D-004 | B5: Scope | C5: Inventory | D5: Inventory history cannot be pulled: only today's snapshot | E5: Business confirmed; ERP has no historical stock report | F5: Stock trends impossible for past dates; each unsaved day is lost | G5: Daily snapshot fact; history approximated by rolling back through movements | H5: Open - ERP team | I5: Start saving the ERP, Blinkit and Instamart stock reports daily into a dated folder | J5: High | K5: ERP team
A6: D-005 | B6: Scope | C6: Blinkit / Instamart | D6: Blinkit return sheet (and Instamart's, if any) not received | E6: Business confirmed returns are in a separate sheet | F6: Quick-commerce returns missing; net sales overstated | G6: Will be registered as a new source when received | H6: Open - business | I6: Will be shared when available | J6: Medium | K6: Business (you)
A7: D-006 | B7: Scope | C7: Franchise / SIS | D7: No sell-out data from franchise and SIS stores | E7: Only sell-in invoices exist in the ERP | F7: Stock AI reads stock that later comes back as demand | G7: Demand for these channels uses net sales after returns until sell-out arrives | H7: Open - business | I7: Business will work out how to extract it | J7: Medium | K7: Business (you)
A8: D-007 | B8: Scope | C8: Blinkit / Instamart | D8: No Blinkit or Instamart invoices found in the ERP for Apr-Sep 2026 | E8: No Kiranakart/Swiggy names in Domestic Sales; no QC channel in Retail Sales; yet Kiranakart appears in returns and Blinkit locations hold ERP stock | F8: Quick-commerce revenue may be missing from ERP-based revenue | G8: Revenue = ERP invoices only; platform sell-out stored separately for demand | H8: Open - business | I8: Partly answered: QC is sale-or-return. Still unclear where QC invoices are raised in the ERP | J8: High | K8: Business (you)
A9: D-008 | B9: Scope | C9: WMS dispatch | D9: Dispatch sample was pasted as text, not shared as a file | E9: Rows pasted in chat, dated Apr 2025 | F9: Cannot test joins (e.g. invoice match rate) until a real export arrives | G9: Model designed from the pasted columns | H9: Open - verify with full data | J9: Low | K9: Business (you)
A10: D-009 | B10: Retail sales | C10: Retail Sales | D10: CHANNELNAME is the billing location, not the sales channel | E10: Values like '08 Jaipur Branch', '24 FBA WH - AMD2' | F10: Channel reports would show warehouses instead of channels | G10: Channel from CONTACTNAME; CHANNELNAME used as location | H10: Resolved (business confirmed) | I10: Use CONTACTNAME for channel | J10: High | K10: Data team
A11: D-010 | B11: Retail sales | C11: Retail Sales | D11: Channel unclear for some payment modes (COD, Snapmint, FNP, ICICI bank, Advance) | E11: COD = 3,947 lines / Rs 52.9 lakh; Snapmint 80; FNP 19; ICICI 18; Advance 3 | F11: Channel split wrong on the dashboard | G11: Resolved through CONTACTNAME: COD and Snapmint are all under Shopify_Customer (website) | H11: Resolved (business confirmed) | I11: Use CONTACTNAME | J11: High | K11: Data team
A12: D-011 | B12: Retail sales | C12: Retail Sales | D12: PRODASSESSABLEVALUE INCLUDES GST despite its name; PRODDOCVALUE is the excl-GST value | E12: PRODDOCVALUE + GST = PRODASSESSABLEVALUE on every product line; e.g. MRP 850 - disc 17 = 833 incl GST; 705.93 excl | F12: Retail revenue overstated by the GST amount | G12: Headline value = PRODDOCVALUE; load fails if the relationship stops holding | H12: Resolved (business confirmed) | I12: Headline sales = excluding GST | J12: High | K12: Data team
A13: D-012 | B13: Retail sales | C13: Retail Sales | D13: PRODDOCVALUE is blank on charge lines (SHIPPING R, Gifting) | E13: Only non-product lines fail the GST check | F13: Charge revenue lost if PRODDOCVALUE used blindly | G13: Excl-GST value for these lines = PRODASSESSABLEVALUE minus GST; kept as CHARGE item type | H13: Handled in model | J13: Low | K13: Data team
A14: D-013 | B14: Retail sales | C14: Retail Sales | D14: Non-product codes appear as invoice lines | E14: SHIPPING R, carry bags COCB04-06, Gifting, packaging codes | F14: Product sales and SKU counts polluted | G14: Every code kept in dim_product with item_type; SKU analysis uses TRADING only | H14: Handled in model | J14: Medium | K14: Data team
A15: D-014 | B15: Retail sales | C15: Retail Sales | D15: Bare contact 'Dileep Essentials Pvt Ltd' on retail invoices | E15: 39 lines, Rs 2 lakh; paid via 'DEPL HYD Store A/c', 'DEPL Jaipur - C-Scheme Exp.' | F15: Mis-classified as a D2C sale | G15: Classified as export through Dileep | H15: Resolved (business confirmed) | I15: All are exports through Dileep | J15: Medium | K15: Data team
A16: D-015 | B16: Retail sales | C16: Retail Sales | D16: Two Nykaa names: 'Nykaa Fashion' (900 lines) and 'Nykaa' (34 lines) | E16: Payment modes 'Prepaid - Nykaa Fashion' and 'Prepaid - Nykaa' | F16: Nykaa split across two channels | G16: Proposed: one channel 'Nykaa' with the two names kept as sub-channels | H16: Assumed - please confirm | J16: Low | K16: Business (you)
A17: D-016 | B17: Retail sales | C17: Retail Sales | D17: 144 Jaipur Branch rows have a blank payment mode | E17: All at '08 Jaipur Branch' | F17: Payment-type analysis incomplete | G17: Channel comes from CONTACTNAME, so not blocking | H17: Handled in model | J17: Low | K17: ERP team
A18: D-017 | B18: Retail sales | C18: Retail Sales | D18: Almost no returns inside the sales file | E18: Only 19 credit notes in 25,899 lines | F18: Returns under-counted | G18: Returns loaded from the dedicated return registers | H18: Resolved (business confirmed) | I18: Return data sheets provided | J18: High | K18: Data team
A19: D-018 | B19: Retail sales | C19: Retail Sales, WMS | D19: Customer personal data (names, phones, emails, addresses) | E19: Present in Retail Sales and WMS dispatch | F19: Privacy and compliance risk | G19: PII stays only in the restricted raw layer; core and mart hold pincode/city/state only | H19: Handled in model | J19: High | K19: Data team
A20: D-019 | B20: Domestic sales | C20: Domestic Sales | D20: CONTACTNAME mixes B2B, franchise, SIS, quick commerce, group exports and employees | E20: 117 distinct accounts in the sample | F20: Sale-or-return stock counted as final revenue | G20: Separate partner types; B2B = final, franchise/SIS/QC = sale-or-return | H20: Open - business | I20: Rules confirmed. Billing names of franchise, SIS and QC partners still to be supplied | J20: High | K20: Business (you)
A21: D-020 | B21: Domestic sales | C21: Domestic Sales | D21: Invoices to Dileep group companies | E21: 54 lines, 15 bills, Rs 21.4 lakh (7.75% of domestic taxable), mostly Dileep Crafts | F21: Related-party sales inflate revenue and distort margin | G21: Partner type GROUP_EXPORT: exports at cost, shown as own channel | H21: Resolved (business confirmed) | I21: Exports go through Dileep, billed cost-to-cost | J21: High | K21: Data team
A22: D-021 | B22: Domestic sales | C22: Domestic Sales | D22: Low unit prices on Dileep Industries and Dileep Jewellery bills | E22: Rs 5-25 per unit, no discount (e.g. 280 units for Rs 1,606) | F22: Could look like data errors | G22: Kept as recorded | H22: Resolved (business confirmed) | I22: These are cost prices | J22: Low | K22: Data team
A23: D-022 | B23: Domestic sales | C23: Domestic Sales | D23: CORRECTION: earlier example (price 1,855.93, discount 1,855.09, taxable 0.84) was an Ayush Baid (employee) line, NOT a Dileep bill | E23: Checked: only 2 Dileep lines have a near-100% discount (Sampling Unit Rs 0.97, Potteries Rs 0.96) | F23: Wrong conclusion about Dileep pricing | G23: Record corrected | H23: Resolved (business confirmed) | I23: Corrected in this log | J23: Low | K23: Data team
A24: D-023 | B24: Domestic sales | C24: Domestic Sales | D24: Lines billed at normal price with a 99-100% discount (near-free) | E24: 106 lines, 60 bills, Rs 63 total: Ayush Baid 42, Sundry Customer 22, Tanishq/Titan 14, others | F24: Free units counted as sold: demand inflated for Stock AI; B2B sample units counted as B2B sales | G24: Proposed: flag lines with >=99% discount as 'free / sample issue' and exclude them from demand | H24: Open - business | I24: Are these samples / free issues? | J24: High | K24: Business (you)
A25: D-024 | B25: Domestic sales | C25: Domestic Sales | D25: 'Sundry Customer' is a catch-all account | E25: 171 lines, 21 bills, Rs 4,960 taxable; products incl. cake stand, paper bags, tissue, gift cards | F25: Default rule would treat it as an EMPLOYEE (not on business list) | G25: Held as UNCLASSIFIED until answered | H25: Open - business | I25: What is Sundry Customer (walk-in / cash B2B / misc)? | J25: Medium | K25: Business (you)
A26: D-025 | B26: Domestic sales | C26: Domestic Sales | D26: 209 lines have a blank Taxable value | E26: Mostly carry bags (COCB04-11); 146 on Sundry Customer; Net Amount is present on all of them | F26: Revenue lost for these lines if Taxable used blindly | G26: Proposed: Taxable = Net Amount - Total Tax (relationship holds on 100% of other lines), flagged as derived | H26: Handled in model | J26: Medium | K26: Data team
A27: D-026 | B27: Domestic sales | C27: Domestic Sales | D27: Net Amount INCLUDES GST | E27: Taxable + Total Tax = Net Amount on 100% of 5,042 lines | F27: Revenue overstated if Net Amount used | G27: Headline value = Taxable | H27: Resolved (business confirmed) | I27: Headline sales = excluding GST | J27: High | K27: Data team
A28: D-027 | B28: Domestic sales | C28: Domestic Sales | D28: Direct export rows to Singapore, although exports are said to go through Dileep | E28: 2 lines to 'Hindustan Exports', Rs 1 each | F28: Unclear classification | G28: Held as EXPORT_CUSTOMER; Rs 1 lines also fall under the near-free issue | H28: Open - business | I28: Are these samples to an exporter? | J28: Low | K28: Business (you)
A29: D-028 | B29: Domestic sales | C29: Domestic Sales | D29: Person names are employees taking exhibition stock | E29: e.g. Ayush Baid, Riya Sharma | F29: Internal movement counted as B2B sales | G29: Unlisted names = EMPLOYEE by rule; each load reports names classified this way | H29: Resolved (business confirmed) | I29: Any person's name is an employee; no list needed | J29: High | K29: Data team
A30: D-029 | B30: Returns | C30: Retail Sales Return | D30: FBA-named contacts in retail returns | E30: e.g. 'Dileep Essentials Pvt Ltd FBA DED4' | F30: Could be mistaken for internal transfers | G30: Genuine customer returns, received at that FBA warehouse | H30: Resolved (business confirmed) | I30: Customer returns going back to FBA | J30: Medium | K30: Data team
A31: D-030 | B31: Returns | C31: Domestic Sale Return | D31: Person names in domestic returns | E31: e.g. Riya Sharma-Customer, Ayush Baid | F31: Counted as B2B returns | G31: EMPLOYEE by rule; excluded from return-rate metrics | H31: Resolved (business confirmed) | I31: Employees returning exhibition stock | J31: Medium | K31: Data team
A32: D-031 | B32: Returns | C32: Domestic Sale Return | D32: Kiranakart Technologies (Blinkit) appears in domestic returns | E32: Returns found in the domestic return register | F32: Could look misplaced | G32: Unsold stock back from a sale-or-return partner | H32: Resolved (business confirmed) | I32: Blinkit returns unsold stock | J32: Medium | K32: Data team
A33: D-032 | B33: Returns | C33: Domestic Sale Return | D33: Return date field holds several dates joined by ';' | E33: CORRECTED: first read as the same date repeated. Loader found they can DIFFER (437 rows in FY25-26, e.g. '22/11/2024;22/01/2025'); see the goods-receipt issue below | F33: Dates fail to parse or pick the wrong day | G33: Raw keeps the text unchanged; handled with the goods-receipt issue | H33: Handled in model | J33: Medium | K33: Data team
A34: D-033 | B34: Returns | C34: Return files | D34: Return date column name differs by file | E34: Retail: RETURNDATE; Domestic: RTNFROMCUSTDT | F34: Wrong column picked | G34: Mapped explicitly per source | H34: Handled in model | J34: Low | K34: Data team
A35: D-034 | B35: Returns | C35: Retail Sales Return | D35: ~7% of retail returns don't match a sale in the sample | E35: 2,875 of 3,089 bills matched | F35: Returns without their original sale | G35: Expected (sales before Apr 2026); re-check on full data | H35: Open - verify with full data | J35: Low | K35: Data team
A36: D-035 | B36: Returns | C36: Retail Sales Return | D36: Shipping-charge reversal lines in returns | E36: 287 rows with PRODNUM 'SHIPPING R' | F36: Returned 'units' of a non-product | G36: CHARGE item type; excluded from product returns | H36: Handled in model | J36: Low | K36: Data team
A37: D-036 | B37: Returns | C37: Domestic Sale Return | D37: Domestic returns have no clear link to the original invoice | E37: BILLNUM here is the credit note; RTNFROMCUST is the goods receipt | F37: Cannot compute return rate per original B2B invoice | G37: Original bill kept nullable | H37: Open - ERP team | I37: Is the original invoice number stored anywhere in this report? | J37: Low | K37: ERP team
A38: D-037 | B38: Returns | C38: WMS, Returns | D38: RTO (failed delivery) vs customer return after delivery | E38: RTO seen in WMS status; customer returns in return registers | F38: Returns mixed or missed | G38: Both kept, as separate events | H38: Resolved (business confirmed) | I38: Return registers provided | J38: Medium | K38: Data team
A39: D-038 | B39: Stock transfers | C39: Stock Transfer, Inward | D39: Sending / receiving location only encoded in the document number prefix | E39: Prefixes JPR/, THA/, HYD, BAG/, AMD ... ; no location column | F39: Stock movements assigned to the wrong place when a new prefix appears | G39: Interim prefix-to-location table (ref.document_prefix_location) | H39: Open - ERP team | I39: Add a branch / location column to transfer and return exports | J39: High | K39: ERP team
A40: D-039 | B40: Stock transfers | C40: Stock Transfer, Inward | D40: Outward stock never received | E40: 31 of 622 outward documents wholly unreceived = 2,311 units (233 from Jun, 34 from May). CORRECTED total counting SKU lines, incl. partly received documents: 2,794 units in transit (built warehouse, verified independently) | F40: Stock can disappear between locations | G40: In-transit view in mart; age of unreceived transfers reported | H40: Open - ERP team | I40: Why are May/June transfers still unreceived? Are FBA receipts recorded in the ERP? | J40: Medium | K40: ERP team
...

Sheet Legend
A1: Status | B1: Meaning
A2: Resolved (business confirmed) | B2: The business answered; the answer is applied in the model.
A3: Handled in model | B3: A data quirk the model deals with automatically; no business input needed.
A4: Open - business | B4: Waiting on an answer or data from the business.
A5: Open - ERP team | B5: Waiting on a change or answer from the ERP team.
A6: Open - verify with full data | B6: Design is ready; must be re-checked when the full 1.5-year data arrives.
A7: Assumed - please confirm | B7: The model uses a proposed rule until someone confirms or corrects it.
A9: How to update | B9: Change Status and fill 'Answer / resolution' in the Issue Log. Add new issues as new rows with the next D-number. The Summary sheet recalculates.
